Workbook

Sheet Assumptions
A1: Medical Office Lease Analysis – Tenant Rep POV
A2: Clermont, FL 34711 (Four Corners submarket) | 1,500 SF chiropractic suite | Names and address removed | LOI dated 03/27/2026
A3: Legend: blue = input (LOI term); blue on yellow = assumption not in the LOI; black = formula.
A4: LOI TERMS | C4: Source / note
A5: Premises (SF) | B5: 1500 | C5: LOI - premises
A6: Base rent ($/SF/yr, NNN) | B6: 32 | C6: LOI
A7: Annual base rent escalation | B7: 0.03 | C7: LOI - annual escalation
A8: NNN charges – maint/tax/ins ($/SF/yr) | B8: 6.25 | C8: LOI - maintenance, taxes and insurance included in NNN
A9: Initial term (years) | B9: 3 | C9: LOI
A10: Renewal options (#) | B10: 2 | C10: LOI - two renewal options
A11: Renewal option length (years) | B11: 3 | C11: LOI - each option equals the initial term
A12: Free base rent (months) | B12: 1 | C12: LOI - tenant request, applied at lease start
A13: Security deposit (months of total rent) | B13: 1 | C13: LOI - one month of total rent
A14: Due diligence (days) | B14: 30 | C14: LOI
A15: Rent commencement (days after delivery) | B15: 30 | C15: LOI
A16: Corporate guarantee | B16: Yes | C16: LOI
A17: Tenant improvements | B17: Neutral paint + door decal/logo | C17: LOI - cosmetic only; no TI allowance
A18: Tenant broker commission (% of aggregate base rent) | B18: 0.03 | C18: LOI - 3% of aggregate base rent paid by Landlord; also due on renewals
A19: ANALYST ASSUMPTIONS
A20: NNN charge annual growth | B20: 0.03 | C20: Assumption - LOI silent; NNN typically inflates about 3%
A21: Escalation applies in renewal periods (1=yes) | B21: 1 | C21: Assumption - set to 0 to hold rent flat in renewals
A22: Include renewal options in analysis (1=yes) | B22: 0 | C22: Toggle - 0 = initial term only, 1 = include both renewal options
A23: Discount rate (annual) | B23: 0.08 | C23: Assumption - tenant cost of capital
A24: Market base rent ($/SF/yr, NNN) | B24: 32 | C24: Clermont medical office market rent, start of 2026
A26: Practice annual revenue ($) | B26: 450000 | C26: Assumption - illustrative practice revenue
A28: Months analyzed | B28: =(B9+B22*B10*B11)*12 -> 36 | C28: Calculated: (term + toggle x options x option length) x 12

Sheet Summary
A1: Lease Summary & Metrics
A3: ANNUAL CASH FLOW
A4: Lease Year | B4: Phase | C4: Base Rent | D4: Free Rent | E4: NNN Charges | F4: Total Cost | G4: Total $/SF | H4: Monthly Avg | I4: Cumulative
A5: 1 | B5: {=INDEX(Schedule!$C$3:$C$110,(A5-1)*12+1)} -> Initial | C5: =SUMIFS(Schedule!$F$3:$F$110,Schedule!$B$3:$B$110,$A5) -> 48000 | D5: =SUMIFS(Schedule!$G$3:$G$110,Schedule!$B$3:$B$110,$A5) -> -4000 | E5: =SUMIFS(Schedule!$H$3:$H$110,Schedule!$B$3:$B$110,$A5) -> 9375 | F5: =SUM(C5:E5) -> 53375 | G5: =F5/Assumptions!$B$5 -> 35.583333 | H5: =F5/12 -> 4447.9167 | I5: =F5 -> 53375
A6: 2 | B6: {=INDEX(Schedule!$C$3:$C$110,(A6-1)*12+1)} -> Initial | C6: =SUMIFS(Schedule!$F$3:$F$110,Schedule!$B$3:$B$110,$A6) -> 49440 | D6: =SUMIFS(Schedule!$G$3:$G$110,Schedule!$B$3:$B$110,$A6) -> 0 | E6: =SUMIFS(Schedule!$H$3:$H$110,Schedule!$B$3:$B$110,$A6) -> 9656.25 | F6: =SUM(C6:E6) -> 59096.25 | G6: =F6/Assumptions!$B$5 -> 39.3975 | H6: =F6/12 -> 4924.6875 | I6: =I5+F6 -> 112471.25
A7: 3 | B7: {=INDEX(Schedule!$C$3:$C$110,(A7-1)*12+1)} -> Initial | C7: =SUMIFS(Schedule!$F$3:$F$110,Schedule!$B$3:$B$110,$A7) -> 50923.2 | D7: =SUMIFS(Schedule!$G$3:$G$110,Schedule!$B$3:$B$110,$A7) -> 0 | E7: =SUMIFS(Schedule!$H$3:$H$110,Schedule!$B$3:$B$110,$A7) -> 9945.9375 | F7: =SUM(C7:E7) -> 60869.137 | G7: =F7/Assumptions!$B$5 -> 40.579425 | H7: =F7/12 -> 5072.4281 | I7: =I6+F7 -> 173340.39
A8: 4 | B8: {=INDEX(Schedule!$C$3:$C$110,(A8-1)*12+1)} -> Option 1 | C8: =SUMIFS(Schedule!$F$3:$F$110,Schedule!$B$3:$B$110,$A8) -> 0 | D8: =SUMIFS(Schedule!$G$3:$G$110,Schedule!$B$3:$B$110,$A8) -> 0 | E8: =SUMIFS(Schedule!$H$3:$H$110,Schedule!$B$3:$B$110,$A8) -> 0 | F8: =SUM(C8:E8) -> 0 | G8: =F8/Assumptions!$B$5 -> 0 | H8: =F8/12 -> 0 | I8: =I7+F8 -> 173340.39
A9: 5 | B9: {=INDEX(Schedule!$C$3:$C$110,(A9-1)*12+1)} -> Option 1 | C9: =SUMIFS(Schedule!$F$3:$F$110,Schedule!$B$3:$B$110,$A9) -> 0 | D9: =SUMIFS(Schedule!$G$3:$G$110,Schedule!$B$3:$B$110,$A9) -> 0 | E9: =SUMIFS(Schedule!$H$3:$H$110,Schedule!$B$3:$B$110,$A9) -> 0 | F9: =SUM(C9:E9) -> 0 | G9: =F9/Assumptions!$B$5 -> 0 | H9: =F9/12 -> 0 | I9: =I8+F9 -> 173340.39
A10: 6 | B10: {=INDEX(Schedule!$C$3:$C$110,(A10-1)*12+1)} -> Option 1 | C10: =SUMIFS(Schedule!$F$3:$F$110,Schedule!$B$3:$B$110,$A10) -> 0 | D10: =SUMIFS(Schedule!$G$3:$G$110,Schedule!$B$3:$B$110,$A10) -> 0 | E10: =SUMIFS(Schedule!$H$3:$H$110,Schedule!$B$3:$B$110,$A10) -> 0 | F10: =SUM(C10:E10) -> 0 | G10: =F10/Assumptions!$B$5 -> 0 | H10: =F10/12 -> 0 | I10: =I9+F10 -> 173340.39
A11: 7 | B11: {=INDEX(Schedule!$C$3:$C$110,(A11-1)*12+1)} -> Option 2 | C11: =SUMIFS(Schedule!$F$3:$F$110,Schedule!$B$3:$B$110,$A11) -> 0 | D11: =SUMIFS(Schedule!$G$3:$G$110,Schedule!$B$3:$B$110,$A11) -> 0 | E11: =SUMIFS(Schedule!$H$3:$H$110,Schedule!$B$3:$B$110,$A11) -> 0 | F11: =SUM(C11:E11) -> 0 | G11: =F11/Assumptions!$B$5 -> 0 | H11: =F11/12 -> 0 | I11: =I10+F11 -> 173340.39
A12: 8 | B12: {=INDEX(Schedule!$C$3:$C$110,(A12-1)*12+1)} -> Option 2 | C12: =SUMIFS(Schedule!$F$3:$F$110,Schedule!$B$3:$B$110,$A12) -> 0 | D12: =SUMIFS(Schedule!$G$3:$G$110,Schedule!$B$3:$B$110,$A12) -> 0 | E12: =SUMIFS(Schedule!$H$3:$H$110,Schedule!$B$3:$B$110,$A12) -> 0 | F12: =SUM(C12:E12) -> 0 | G12: =F12/Assumptions!$B$5 -> 0 | H12: =F12/12 -> 0 | I12: =I11+F12 -> 173340.39
A13: 9 | B13: {=INDEX(Schedule!$C$3:$C$110,(A13-1)*12+1)} -> Option 2 | C13: =SUMIFS(Schedule!$F$3:$F$110,Schedule!$B$3:$B$110,$A13) -> 0 | D13: =SUMIFS(Schedule!$G$3:$G$110,Schedule!$B$3:$B$110,$A13) -> 0 | E13: =SUMIFS(Schedule!$H$3:$H$110,Schedule!$B$3:$B$110,$A13) -> 0 | F13: =SUM(C13:E13) -> 0 | G13: =F13/Assumptions!$B$5 -> 0 | H13: =F13/12 -> 0 | I13: =I12+F13 -> 173340.39
A14: Total | C14: =SUM(C5:C13) -> 148363.2 | D14: =SUM(D5:D13) -> -4000 | E14: =SUM(E5:E13) -> 28977.188 | F14: =SUM(F5:F13) -> 173340.39
A15: Years beyond the analysis period show zero. Set 'Include renewal options' to 1 on the Assumptions tab to add the two renewal options.
A17: KEY METRICS
A18: Year-1 base rent (before free rent) | B18: =C5 -> 48000
A19: Year-1 total rent (LOI: $57,375 – check) | B19: =C5+E5 -> 57375
A20: Year-1 monthly rate (LOI: $4,781.25 – check) | B20: =(C5+E5)/12 -> 4781.25
A21: Security deposit | B21: =Assumptions!$B$13*(C5+E5)/12 -> 4781.25
A22: Initial-term total cost (net of free rent) | B22: =SUMIFS(F5:F13,A5:A13,"<="&Assumptions!$B$9) -> 173340.39
A23: Total cost over analysis period | B23: =F14 -> 173340.39
A24: Average annual cost over period | B24: =F14/(SUM(Schedule!$D$3:$D$110)/12) -> 57780.129
A25: Gross effective rent $/SF/yr (all-in, net of free) | B25: =B24/Assumptions!$B$5 -> 38.520086
A26: Net effective base rent $/SF/yr (excl. NNN, net of free) | B26: =(C14+D14)/(SUM(Schedule!$D$3:$D$110)/12)/Assumptions!$B$5 -> 32.080711
A27: Free rent value as % of base rent | B27: =-D14/C14 -> 0.026960864
A28: NPV of occupancy cost @ discount rate | B28: =SUM(Schedule!K3:K110) -> 152981.28
A29: Base rent vs. market (Yr 1, %) | B29: =Assumptions!$B$6/Assumptions!$B$24-1 -> 0
A30: Year-1 savings vs. market base rent ($) | B30: =(Assumptions!$B$24-Assumptions!$B$6)*Assumptions!$B$5 -> 0
A31: Occupancy cost % of practice revenue (Yr 1) | B31: =F5/Assumptions!$B$26 -> 0.11861111
A32: Landlord commission (aggregate base rent × %) | B32: =C14*Assumptions!$B$18 -> 4450.896
A33: Revenue needed for 10% occupancy ratio (Yr 1) | B33: =F5/0.1 -> 533750
A36: Notes
A37: The Year-1 free month appears as a negative in the Free Rent column.
A38: Cell B19 ties to the LOI total rent ($57,375) before free rent; the model reconciles to the LOI.

Sheet Sensitivity Analysis
A1: Sensitivity & Scenario Analysis (Initial Term)
A2: Tables 1-4 are Excel Data Tables driven by the cells in I4:J17; keep those equal to the Assumptions base case. Table 5 uses direct formulas. The base case is outlined in each table.
I3: DATA TABLE DRIVERS (keep equal to Assumptions)
A4: Rent step ($/SF) | B4: 1 | I4: Base rent ($/SF/yr) | J4: 32 | K4: Table input
A5: Escalation step | B5: 0.005 | I5: Escalation | J5: 0.03 | K5: Table input
A6: Revenue step ($) | B6: 50000 | I6: Net effective rent ($/SF/yr) | J6: =(Assumptions!$B$5*J4*IF(J5=0,Assumptions!$B$9,((1+J5)^Assumptions!$B$9-1)/J5)-Assumptions!$B$5*J4/12*Assumptions!$B$12)/(Assumptions!$B$9*Assumptions!$B$5) -> 32.080711 | K6: Table 1 output
A9: 1) Net effective base rent ($/SF/yr) – Base rent vs. annual escalation
A10: Net of free rent, excluding NNN.
A11: =(Assumptions!$B$5*J4*IF(J5=0,Assumptions!$B$9,((1+J5)^Assumptions!$B$9-1)/J5)-Assumptions!$B$5*J4/12*Assumptions!$B$12)/(Assumptions!$B$9*Assumptions!$B$5) -> 32.080711 | B11: 0.02 | C11: 0.025 | D11: 0.03 | E11: 0.035 | F11: 0.04 | I11: Free rent (months) | J11: 1 | K11: Table input
A12: 29 | B12: 28.778311 | C12: 28.925486 | D12: 29.073144 | E12: 29.221286 | F12: 29.369911 | I12: Lease term (years) | J12: 3 | K12: Table input
A13: 30 | B13: 29.770667 | C13: 29.922917 | D13: 30.075667 | E13: 30.228917 | F13: 30.382667 | I13: Practice revenue ($) | J13: 450000 | K13: Table input
A14: 31 | B14: 30.763022 | C14: 30.920347 | D14: 31.078189 | E14: 31.236547 | F14: 31.395422
A15: 32 | B15: 31.755378 | C15: 31.917778 | D15: 32.080711 | E15: 32.244178 | F15: 32.408178 | I15: Total initial-term occupancy cost ($) | J15: =Assumptions!$B$5*J4*IF(J5=0,J12,((1+J5)^J12-1)/J5)-Assumptions!$B$5*J4/12*J11+Assumptions!$B$5*Assumptions!$B$8*IF(Assumptions!$B$20=0,J12,((1+Assumptions!$B$20)^J12-1)/Assumptions!$B$20) -> 173340.39 | K15: Table 2 output
A16: 33 | B16: 32.747733 | C16: 32.915208 | D16: 33.083233 | E16: 33.251808 | F16: 33.420933 | I16: Gross effective rent ($/SF/yr) | J16: =J15/(J12*Assumptions!$B$5) -> 38.520086 | K16: Table 3 output
A17: 34 | B17: 33.740089 | C17: 33.912639 | D17: 34.085756 | E17: 34.259439 | F17: 34.433689 | I17: Year-1 occupancy cost (% of revenue) | J17: =A48 -> 0.1275 | K17: Table 4 output
A18: 35 | B18: 34.732444 | C18: 34.910069 | D18: 35.088278 | E18: 35.267069 | F18: 35.446444
A22: 2) Total initial-term occupancy cost ($) – Base rent vs. free-rent months
A23: Base rent net of free months plus NNN over the initial term.
A24: =J15 -> 173340.39 | B24: 0 | C24: 1 | D24: 2 | E24: 3 | F24: 4
A25: 29 | B25: 163431.34 | C25: 159806.34 | D25: 156181.34 | E25: 152556.34 | F25: 148931.34
A26: 30 | B26: 168067.69 | C26: 164317.69 | D26: 160567.69 | E26: 156817.69 | F26: 153067.69
A27: 31 | B27: 172704.04 | C27: 168829.04 | D27: 164954.04 | E27: 161079.04 | F27: 157204.04
A28: 32 | B28: 177340.39 | C28: 173340.39 | D28: 169340.39 | E28: 165340.39 | F28: 161340.39
A29: 33 | B29: 181976.74 | C29: 177851.74 | D29: 173726.74 | E29: 169601.74 | F29: 165476.74
A30: 34 | B30: 186613.09 | C30: 182363.09 | D30: 178113.09 | E30: 173863.09 | F30: 169613.09
A31: 35 | B31: 191249.44 | C31: 186874.44 | D31: 182499.44 | E31: 178124.44 | F31: 173749.44
A35: 3) Gross effective rent ($/SF/yr, base + NNN) – Free-rent months vs. lease term
A36: Shows how a free month is worth more on a shorter term.
A37: =J16 -> 38.520086 | B37: 2 | C37: 3 | D37: 4 | E37: 5 | F37: 6 | G37: 7
A38: 0 | B38: 38.82375 | C38: 39.408975 | D38: 40.005933 | E38: 40.614889 | F38: 41.236113 | G38: 41.869883
A39: 1 | B39: 37.490417 | C39: 38.520086 | D39: 39.339267 | E39: 40.081556 | F39: 40.791669 | G39: 41.48893
A40: 2 | B40: 36.157083 | C40: 37.631197 | D40: 38.6726 | E40: 39.548222 | F40: 40.347224 | G40: 41.107978
A41: 3 | B41: 34.82375 | C41: 36.742308 | D41: 38.005933 | E41: 39.014889 | F41: 39.90278 | G41: 40.727025
A42: 4 | B42: 33.490417 | C42: 35.853419 | D42: 37.339267 | E42: 38.481556 | F42: 39.458335 | G42: 40.346073
A46: 4) Year-1 occupancy cost as % of practice revenue – Base rent vs. revenue
A47: Year-1 base + NNN before free rent ÷ revenue. Medical/chiro benchmark roughly 8–12%.
A48: =(Assumptions!$B$5*J4+Assumptions!$B$5*Assumptions!$B$8)/J13 -> 0.1275 | B48: 350000 | C48: 400000 | D48: 450000 | E48: 500000 | F48: 550000
A49: 29 | B49: 0.15107143 | C49: 0.1321875 | D49: 0.1175 | E49: 0.10575 | F49: 0.096136364
A50: 30 | B50: 0.15535714 | C50: 0.1359375 | D50: 0.12083333 | E50: 0.10875 | F50: 0.098863636
A51: 31 | B51: 0.15964286 | C51: 0.1396875 | D51: 0.12416667 | E51: 0.11175 | F51: 0.10159091
...

Sheet Schedule
A1: Monthly Rent Schedule (Initial Term and Renewal Options)
A2: Month | B2: Lease Yr | C2: Phase | D2: In Analysis | E2: Base Rent ($/SF/yr) | F2: Base Rent ($) | G2: Free Rent ($) | H2: NNN Charges ($) | I2: Total Occupancy Cost ($) | J2: Discount Factor | K2: PV ($)
A3: =1 -> 1 | B3: =ROUNDUP(A3/12,0) -> 1 | C3: =IF(B3<=Assumptions!$B$9,"Initial",IF(B3<=Assumptions!$B$9+Assumptions!$B$11,"Option 1","Option 2")) -> Initial | D3: =IF(A3<=Assumptions!$B$28,1,0) -> 1 | E3: =Assumptions!$B$6*(1+Assumptions!$B$7)^IF(B3<=Assumptions!$B$9,B3-1,Assumptions!$B$9-1+Assumptions!$B$21*(B3-Assumptions!$B$9)) -> 32 | F3: =E3*Assumptions!$B$5/12*D3 -> 4000 | G3: =-IF(A3<=Assumptions!$B$12,F3,0) -> -4000 | H3: =Assumptions!$B$8*(1+Assumptions!$B$20)^(B3-1)*Assumptions!$B$5/12*D3 -> 781.25 | I3: =F3+G3+H3 -> 781.25 | J3: =1/(1+Assumptions!$B$23/12)^A3 -> 0.99337748 | K3: =I3*J3 -> 776.07616
A4: 2 | B4: =ROUNDUP(A4/12,0) -> 1 | C4: =IF(B4<=Assumptions!$B$9,"Initial",IF(B4<=Assumptions!$B$9+Assumptions!$B$11,"Option 1","Option 2")) -> Initial | D4: =IF(A4<=Assumptions!$B$28,1,0) -> 1 | E4: =Assumptions!$B$6*(1+Assumptions!$B$7)^IF(B4<=Assumptions!$B$9,B4-1,Assumptions!$B$9-1+Assumptions!$B$21*(B4-Assumptions!$B$9)) -> 32 | F4: =E4*Assumptions!$B$5/12*D4 -> 4000 | G4: =-IF(A4<=Assumptions!$B$12,F4,0) -> 0 | H4: =Assumptions!$B$8*(1+Assumptions!$B$20)^(B4-1)*Assumptions!$B$5/12*D4 -> 781.25 | I4: =F4+G4+H4 -> 4781.25 | J4: =1/(1+Assumptions!$B$23/12)^A4 -> 0.98679882 | K4: =I4*J4 -> 4718.1319
A5: 3 | B5: =ROUNDUP(A5/12,0) -> 1 | C5: =IF(B5<=Assumptions!$B$9,"Initial",IF(B5<=Assumptions!$B$9+Assumptions!$B$11,"Option 1","Option 2")) -> Initial | D5: =IF(A5<=Assumptions!$B$28,1,0) -> 1 | E5: =Assumptions!$B$6*(1+Assumptions!$B$7)^IF(B5<=Assumptions!$B$9,B5-1,Assumptions!$B$9-1+Assumptions!$B$21*(B5-Assumptions!$B$9)) -> 32 | F5: =E5*Assumptions!$B$5/12*D5 -> 4000 | G5: =-IF(A5<=Assumptions!$B$12,F5,0) -> 0 | H5: =Assumptions!$B$8*(1+Assumptions!$B$20)^(B5-1)*Assumptions!$B$5/12*D5 -> 781.25 | I5: =F5+G5+H5 -> 4781.25 | J5: =1/(1+Assumptions!$B$23/12)^A5 -> 0.98026373 | K5: =I5*J5 -> 4686.886
A6: 4 | B6: =ROUNDUP(A6/12,0) -> 1 | C6: =IF(B6<=Assumptions!$B$9,"Initial",IF(B6<=Assumptions!$B$9+Assumptions!$B$11,"Option 1","Option 2")) -> Initial | D6: =IF(A6<=Assumptions!$B$28,1,0) -> 1 | E6: =Assumptions!$B$6*(1+Assumptions!$B$7)^IF(B6<=Assumptions!$B$9,B6-1,Assumptions!$B$9-1+Assumptions!$B$21*(B6-Assumptions!$B$9)) -> 32 | F6: =E6*Assumptions!$B$5/12*D6 -> 4000 | G6: =-IF(A6<=Assumptions!$B$12,F6,0) -> 0 | H6: =Assumptions!$B$8*(1+Assumptions!$B$20)^(B6-1)*Assumptions!$B$5/12*D6 -> 781.25 | I6: =F6+G6+H6 -> 4781.25 | J6: =1/(1+Assumptions!$B$23/12)^A6 -> 0.97377192 | K6: =I6*J6 -> 4655.847
A7: 5 | B7: =ROUNDUP(A7/12,0) -> 1 | C7: =IF(B7<=Assumptions!$B$9,"Initial",IF(B7<=Assumptions!$B$9+Assumptions!$B$11,"Option 1","Option 2")) -> Initial | D7: =IF(A7<=Assumptions!$B$28,1,0) -> 1 | E7: =Assumptions!$B$6*(1+Assumptions!$B$7)^IF(B7<=Assumptions!$B$9,B7-1,Assumptions!$B$9-1+Assumptions!$B$21*(B7-Assumptions!$B$9)) -> 32 | F7: =E7*Assumptions!$B$5/12*D7 -> 4000 | G7: =-IF(A7<=Assumptions!$B$12,F7,0) -> 0 | H7: =Assumptions!$B$8*(1+Assumptions!$B$20)^(B7-1)*Assumptions!$B$5/12*D7 -> 781.25 | I7: =F7+G7+H7 -> 4781.25 | J7: =1/(1+Assumptions!$B$23/12)^A7 -> 0.9673231 | K7: =I7*J7 -> 4625.0136
A8: 6 | B8: =ROUNDUP(A8/12,0) -> 1 | C8: =IF(B8<=Assumptions!$B$9,"Initial",IF(B8<=Assumptions!$B$9+Assumptions!$B$11,"Option 1","Option 2")) -> Initial | D8: =IF(A8<=Assumptions!$B$28,1,0) -> 1 | E8: =Assumptions!$B$6*(1+Assumptions!$B$7)^IF(B8<=Assumptions!$B$9,B8-1,Assumptions!$B$9-1+Assumptions!$B$21*(B8-Assumptions!$B$9)) -> 32 | F8: =E8*Assumptions!$B$5/12*D8 -> 4000 | G8: =-IF(A8<=Assumptions!$B$12,F8,0) -> 0 | H8: =Assumptions!$B$8*(1+Assumptions!$B$20)^(B8-1)*Assumptions!$B$5/12*D8 -> 781.25 | I8: =F8+G8+H8 -> 4781.25 | J8: =1/(1+Assumptions!$B$23/12)^A8 -> 0.96091699 | K8: =I8*J8 -> 4594.3843
A9: 7 | B9: =ROUNDUP(A9/12,0) -> 1 | C9: =IF(B9<=Assumptions!$B$9,"Initial",IF(B9<=Assumptions!$B$9+Assumptions!$B$11,"Option 1","Option 2")) -> Initial | D9: =IF(A9<=Assumptions!$B$28,1,0) -> 1 | E9: =Assumptions!$B$6*(1+Assumptions!$B$7)^IF(B9<=Assumptions!$B$9,B9-1,Assumptions!$B$9-1+Assumptions!$B$21*(B9-Assumptions!$B$9)) -> 32 | F9: =E9*Assumptions!$B$5/12*D9 -> 4000 | G9: =-IF(A9<=Assumptions!$B$12,F9,0) -> 0 | H9: =Assumptions!$B$8*(1+Assumptions!$B$20)^(B9-1)*Assumptions!$B$5/12*D9 -> 781.25 | I9: =F9+G9+H9 -> 4781.25 | J9: =1/(1+Assumptions!$B$23/12)^A9 -> 0.9545533 | K9: =I9*J9 -> 4563.958
A10: 8 | B10: =ROUNDUP(A10/12,0) -> 1 | C10: =IF(B10<=Assumptions!$B$9,"Initial",IF(B10<=Assumptions!$B$9+Assumptions!$B$11,"Option 1","Option 2")) -> Initial | D10: =IF(A10<=Assumptions!$B$28,1,0) -> 1 | E10: =Assumptions!$B$6*(1+Assumptions!$B$7)^IF(B10<=Assumptions!$B$9,B10-1,Assumptions!$B$9-1+Assumptions!$B$21*(B10-Assumptions!$B$9)) -> 32 | F10: =E10*Assumptions!$B$5/12*D10 -> 4000 | G10: =-IF(A10<=Assumptions!$B$12,F10,0) -> 0 | H10: =Assumptions!$B$8*(1+Assumptions!$B$20)^(B10-1)*Assumptions!$B$5/12*D10 -> 781.25 | I10: =F10+G10+H10 -> 4781.25 | J10: =1/(1+Assumptions!$B$23/12)^A10 -> 0.94823175 | K10: =I10*J10 -> 4533.7331
A11: 9 | B11: =ROUNDUP(A11/12,0) -> 1 | C11: =IF(B11<=Assumptions!$B$9,"Initial",IF(B11<=Assumptions!$B$9+Assumptions!$B$11,"Option 1","Option 2")) -> Initial | D11: =IF(A11<=Assumptions!$B$28,1,0) -> 1 | E11: =Assumptions!$B$6*(1+Assumptions!$B$7)^IF(B11<=Assumptions!$B$9,B11-1,Assumptions!$B$9-1+Assumptions!$B$21*(B11-Assumptions!$B$9)) -> 32 | F11: =E11*Assumptions!$B$5/12*D11 -> 4000 | G11: =-IF(A11<=Assumptions!$B$12,F11,0) -> 0 | H11: =Assumptions!$B$8*(1+Assumptions!$B$20)^(B11-1)*Assumptions!$B$5/12*D11 -> 781.25 | I11: =F11+G11+H11 -> 4781.25 | J11: =1/(1+Assumptions!$B$23/12)^A11 -> 0.94195207 | K11: =I11*J11 -> 4503.7083
A12: 10 | B12: =ROUNDUP(A12/12,0) -> 1 | C12: =IF(B12<=Assumptions!$B$9,"Initial",IF(B12<=Assumptions!$B$9+Assumptions!$B$11,"Option 1","Option 2")) -> Initial | D12: =IF(A12<=Assumptions!$B$28,1,0) -> 1 | E12: =Assumptions!$B$6*(1+Assumptions!$B$7)^IF(B12<=Assumptions!$B$9,B12-1,Assumptions!$B$9-1+Assumptions!$B$21*(B12-Assumptions!$B$9)) -> 32 | F12: =E12*Assumptions!$B$5/12*D12 -> 4000 | G12: =-IF(A12<=Assumptions!$B$12,F12,0) -> 0 | H12: =Assumptions!$B$8*(1+Assumptions!$B$20)^(B12-1)*Assumptions!$B$5/12*D12 -> 781.25 | I12: =F12+G12+H12 -> 4781.25 | J12: =1/(1+Assumptions!$B$23/12)^A12 -> 0.93571398 | K12: =I12*J12 -> 4473.8825
A13: 11 | B13: =ROUNDUP(A13/12,0) -> 1 | C13: =IF(B13<=Assumptions!$B$9,"Initial",IF(B13<=Assumptions!$B$9+Assumptions!$B$11,"Option 1","Option 2")) -> Initial | D13: =IF(A13<=Assumptions!$B$28,1,0) -> 1 | E13: =Assumptions!$B$6*(1+Assumptions!$B$7)^IF(B13<=Assumptions!$B$9,B13-1,Assumptions!$B$9-1+Assumptions!$B$21*(B13-Assumptions!$B$9)) -> 32 | F13: =E13*Assumptions!$B$5/12*D13 -> 4000 | G13: =-IF(A13<=Assumptions!$B$12,F13,0) -> 0 | H13: =Assumptions!$B$8*(1+Assumptions!$B$20)^(B13-1)*Assumptions!$B$5/12*D13 -> 781.25 | I13: =F13+G13+H13 -> 4781.25 | J13: =1/(1+Assumptions!$B$23/12)^A13 -> 0.9295172 | K13: =I13*J13 -> 4444.2541
A14: 12 | B14: =ROUNDUP(A14/12,0) -> 1 | C14: =IF(B14<=Assumptions!$B$9,"Initial",IF(B14<=Assumptions!$B$9+Assumptions!$B$11,"Option 1","Option 2")) -> Initial | D14: =IF(A14<=Assumptions!$B$28,1,0) -> 1 | E14: =Assumptions!$B$6*(1+Assumptions!$B$7)^IF(B14<=Assumptions!$B$9,B14-1,Assumptions!$B$9-1+Assumptions!$B$21*(B14-Assumptions!$B$9)) -> 32 | F14: =E14*Assumptions!$B$5/12*D14 -> 4000 | G14: =-IF(A14<=Assumptions!$B$12,F14,0) -> 0 | H14: =Assumptions!$B$8*(1+Assumptions!$B$20)^(B14-1)*Assumptions!$B$5/12*D14 -> 781.25 | I14: =F14+G14+H14 -> 4781.25 | J14: =1/(1+Assumptions!$B$23/12)^A14 -> 0.92336145 | K14: =I14*J14 -> 4414.822
A15: 13 | B15: =ROUNDUP(A15/12,0) -> 2 | C15: =IF(B15<=Assumptions!$B$9,"Initial",IF(B15<=Assumptions!$B$9+Assumptions!$B$11,"Option 1","Option 2")) -> Initial | D15: =IF(A15<=Assumptions!$B$28,1,0) -> 1 | E15: =Assumptions!$B$6*(1+Assumptions!$B$7)^IF(B15<=Assumptions!$B$9,B15-1,Assumptions!$B$9-1+Assumptions!$B$21*(B15-Assumptions!$B$9)) -> 32.96 | F15: =E15*Assumptions!$B$5/12*D15 -> 4120 | G15: =-IF(A15<=Assumptions!$B$12,F15,0) -> 0 | H15: =Assumptions!$B$8*(1+Assumptions!$B$20)^(B15-1)*Assumptions!$B$5/12*D15 -> 804.6875 | I15: =F15+G15+H15 -> 4924.6875 | J15: =1/(1+Assumptions!$B$23/12)^A15 -> 0.91724648 | K15: =I15*J15 -> 4517.1523
... A110: 108 | B110: =ROUNDUP(A110/12,0) -> 9 | C110: =IF(B110<=Assumptions!$B$9,"Initial",IF(B110<=Assumptions!$B$9+Assumptions!$B$11,"Option 1","Option 2")) -> Option 2 | D110: =IF(A110<=Assumptions!$B$28,1,0) -> 0 | E110: =Assumptions!$B$6*(1+Assumptions!$B$7)^IF(B110<=Assumptions!$B$9,B110-1,Assumptions!$B$9-1+Assumptions!$B$21*(B110-Assumptions!$B$9)) -> 40.536643 | F110: =E110*Assumptions!$B$5/12*D110 -> 0 | G110: =-IF(A110<=Assumptions!$B$12,F110,0) -> 0 | H110: =Assumptions!$B$8*(1+Assumptions!$B$20)^(B110-1)*Assumptions!$B$5/12*D110 -> 0 | I110: =F110+G110+H110 -> 0 | J110: =1/(1+Assumptions!$B$23/12)^A110 -> 0.48791669 | K110: =I110*J110 -> 0
