Workbook

Sheet Inputs
A1: Industrial Warehouse Acquisition - Inputs & Assumptions
A2: Blue = editable input | Black = formula | Yellow fill = assumption not provided by client
A3: PROPERTY & LEASE (NNN)
A4: Purchase price ($) | B4: 270000 | D4: Listing price per client ($270,000)
A5: Building size (SF) | B5: 2016 | D5: Per client (2,016 SF)
A6: Base rent ($/SF/yr) | B6: 14 | D6: Per client
A7: NNN charges ($/SF/yr) | B7: 4.5 | D7: Per client (taxes, insurance, CAM paid by tenant)
A8: Annual base rent growth | B8: 0.035 | D8: Per client (3.5% annual escalation)
A9: Annual expense growth (NNN & other) | B9: 0.03 | D9: ASSUMPTION
A10: Vacancy / credit loss (on base rent) | B10: 0.03 | D10: ASSUMPTION - reserve for single tenant
A11: NNN recovery rate | B11: 1 | D11: ASSUMPTION - 100% = tenant reimburses all NNN expenses
A12: Property mgmt fee (% of effective base rent) | B12: 0.02 | D12: ASSUMPTION
A13: Non-recoverable expenses ($/SF/yr) | B13: 0.1 | D13: ASSUMPTION - landlord legal/admin/accounting
A14: Capital / roof reserve ($/SF/yr) | B14: 0.15 | D14: ASSUMPTION - landlord-responsible structure & roof
A15: Acquisition closing costs (% of price) | B15: 0.015 | D15: ASSUMPTION - title, legal, survey, Phase I, inspections, FL doc stamps on mortgage/intangible tax are in loan costs
A17: FINANCING SCENARIOS
B18: Client $130K Down | C18: Alt: 70% LTV
A19: Down payment ($) | B19: 130000 | C19: =$B$4*(1-C20) -> 81000 | D19: Client column = the $130,000 down payment provided (about 43% down). Alt column = typical max bank leverage, for comparison
A20: Loan-to-value (LTV) | B20: =1-B19/$B$4 -> 0.51851852 | C20: 0.7 | D20: Banks typically lend 65-75% LTV on investment industrial (ASSUMPTION for Alt column)
A21: Loan amount ($) | B21: =$B$4-B19 -> 140000 | C21: =$B$4-C19 -> 189000
A22: Interest rate (fixed) | B22: 0.0675 | C22: 0.0675 | D22: ASSUMPTION - approx. commercial fixed rate for Central FL; get live lender quotes
A23: Amortization (years) | B23: 25 | C23: 25 | D23: Typical commercial: 20-25 yr amortization, 5-10 yr term
A24: Loan term / balloon (years) | B24: 10 | C24: 10
A25: Origination fee (% of loan) | B25: 0.01 | C25: 0.01
A26: Other lender / third-party costs ($) | B26: 5000 | C26: 5000
A27: Minimum DSCR required by lender | B27: 1.25 | C27: 1.25 | D27: Typical bank covenant 1.20x-1.25x
A29: EXIT / HOLD PERIODS
A30: Exit (terminal) cap rate | B30: 0.07 | D30: ASSUMPTION - applied to Year N+1 NOI; set slightly above going-in cap
A31: Selling costs (% of sale price) | B31: 0.035 | D31: ASSUMPTION - broker ~2.5% + FL deed doc stamps 0.70% + legal
A32: Hold period 1 (years) | B32: 5 | D32: Per client
A33: Hold period 2 (years) | B33: 8 | D33: Per client
A34: Hold period 3 (years) | B34: 10 | D34: Per client (max 10)
A36: Notes: Analysis is pre-income-tax (no depreciation / 1031 / cap-gains modeling). Client must review with a CPA & lender.

Sheet Summary
A1: Industrial Warehouse Acquisition - NNN Buy & Hold Summary
A2: Pre-tax. Only Change assumptions on the Inputs tab.
A4: DEAL & FINANCING
B5: Client $130K Down | C5: Alt: 70% LTV
A6: Purchase price | B6: ='PF Client 130K'!B28 -> 270000 | C6: ='PF Alt 70 LTV'!B28 -> 270000
A7: Down payment | B7: =Inputs!B19 -> 130000 | C7: =Inputs!C19 -> 81000
A8: Total equity required (incl. costs) | B8: ='PF Client 130K'!B33 -> 140450 | C8: ='PF Alt 70 LTV'!B33 -> 91940
A9: Loan amount | B9: ='PF Client 130K'!B32 -> 140000 | C9: ='PF Alt 70 LTV'!B32 -> 189000
A10: Loan-to-value | B10: ='PF Client 130K'!B37 -> 0.51851852 | C10: ='PF Alt 70 LTV'!B37 -> 0.7
A11: Interest rate | B11: =Inputs!B22 -> 0.0675 | C11: =Inputs!C22 -> 0.0675
A12: Annual debt service | B12: ='PF Client 130K'!B35 -> 11607.314 | C12: ='PF Alt 70 LTV'!B35 -> 15669.873
A13: Year-1 NOI | B13: ='PF Client 130K'!C16 -> 26325.734 | C13: ='PF Alt 70 LTV'!C16 -> 26325.734
A14: Going-in cap rate | B14: ='PF Client 130K'!B36 -> 0.09750272 | C14: ='PF Alt 70 LTV'!B36 -> 0.09750272
A15: Year-1 DSCR | B15: ='PF Client 130K'!C22 -> 2.2680299 | C15: ='PF Alt 70 LTV'!C22 -> 1.6800222
A16: Year-1 cash flow after debt | B16: ='PF Client 130K'!C23 -> 14718.421 | C16: ='PF Alt 70 LTV'!C23 -> 10655.861
A17: Year-1 cash-on-cash | B17: ='PF Client 130K'!C24 -> 0.10479474 | C17: ='PF Alt 70 LTV'!C24 -> 0.11590016
A18: Max loan at lender min DSCR | B18: ='PF Client 130K'!B38 -> 254019.35 | C18: ='PF Alt 70 LTV'!B38 -> 254019.35
A19: Max LTV at lender min DSCR | B19: ='PF Client 130K'!B39 -> 0.9408124 | C19: ='PF Alt 70 LTV'!B39 -> 0.9408124
A20: Meets lender min DSCR in Year 1? | B20: =IF(B15>=Inputs!B27,"YES","NO - below "&TEXT(Inputs!B27,"0.00")&"x") -> YES | C20: =IF(C15>=Inputs!C27,"YES","NO - below "&TEXT(Inputs!C27,"0.00")&"x") -> YES
A22: RETURNS BY HOLD PERIOD (SALE AT END OF HOLD)
B23: $130K 5-YR | C23: $130K 8-YR | D23: $130K 10-YR | E23: 70% LTV 5-YR | F23: 70% LTV 8-YR | G23: 70% LTV 10-YR
A24: Hold period (years) | B24: ='PF Client 130K'!B42 -> 5 | C24: ='PF Client 130K'!C42 -> 8 | D24: ='PF Client 130K'!D42 -> 10 | E24: ='PF Alt 70 LTV'!B42 -> 5 | F24: ='PF Alt 70 LTV'!C42 -> 8 | G24: ='PF Alt 70 LTV'!D42 -> 10
A25: Gross sale price | B25: ='PF Client 130K'!B44 -> 446871.91 | C25: ='PF Client 130K'!C44 -> 495588.35 | D25: ='PF Client 130K'!D44 -> 530980.8 | E25: ='PF Alt 70 LTV'!B44 -> 446871.91 | F25: ='PF Alt 70 LTV'!C44 -> 495588.35 | G25: ='PF Alt 70 LTV'!D44 -> 530980.8
A26: Loan payoff | B26: ='PF Client 130K'!B46 -> -127212.25 | C26: ='PF Client 130K'!C46 -> -117199.2 | D26: ='PF Client 130K'!D46 -> -109307.92 | E26: ='PF Alt 70 LTV'!B46 -> -171736.53 | F26: ='PF Alt 70 LTV'!C46 -> -158218.92 | G26: ='PF Alt 70 LTV'!D46 -> -147565.69
A27: Net sale proceeds to equity | B27: ='PF Client 130K'!B47 -> 304019.15 | C27: ='PF Client 130K'!C47 -> 361043.56 | D27: ='PF Client 130K'!D47 -> 403088.55 | E27: ='PF Alt 70 LTV'!B47 -> 259494.87 | F27: ='PF Alt 70 LTV'!C47 -> 320023.84 | G27: ='PF Alt 70 LTV'!D47 -> 364830.78
A28: Cumulative cash flow during hold | B28: ='PF Client 130K'!B48 -> 83161.163 | C28: ='PF Client 130K'!C48 -> 145514.11 | D28: ='PF Client 130K'!D48 -> 192899.23 | E28: ='PF Alt 70 LTV'!B48 -> 62848.364 | F28: ='PF Alt 70 LTV'!C48 -> 113013.63 | G28: ='PF Alt 70 LTV'!D48 -> 152273.63
A29: Total profit | B29: ='PF Client 130K'!B49 -> 246730.31 | C29: ='PF Client 130K'!C49 -> 366107.67 | D29: ='PF Client 130K'!D49 -> 455537.79 | E29: ='PF Alt 70 LTV'!B49 -> 230403.23 | F29: ='PF Alt 70 LTV'!C49 -> 341097.47 | G29: ='PF Alt 70 LTV'!D49 -> 425164.42
A30: Equity multiple | B30: ='PF Client 130K'!B50 -> 2.7567128 | C30: ='PF Client 130K'!C50 -> 3.6066762 | D30: ='PF Client 130K'!D50 -> 4.2434161 | E30: ='PF Alt 70 LTV'!B50 -> 3.5060173 | F30: ='PF Alt 70 LTV'!C50 -> 4.7100008 | G30: ='PF Alt 70 LTV'!D50 -> 5.6243682
A31: Levered IRR (pre-tax) | B31: ='PF Client 130K'!B51 -> 0.25568276 | C31: ='PF Client 130K'!C51 -> 0.21312171 | D31: ='PF Client 130K'!D51 -> 0.19906171 | E31: ='PF Alt 70 LTV'!B51 -> 0.32357463 | F31: ='PF Alt 70 LTV'!C51 -> 0.2609637 | G31: ='PF Alt 70 LTV'!D51 -> 0.24036179
A32: Average cash-on-cash | B32: ='PF Client 130K'!B52 -> 0.11842102 | C32: ='PF Client 130K'!C52 -> 0.12950704 | D32: ='PF Client 130K'!D52 -> 0.1373437 | E32: ='PF Alt 70 LTV'!B52 -> 0.13671604 | F32: ='PF Alt 70 LTV'!C52 -> 0.15365133 | G32: ='PF Alt 70 LTV'!D52 -> 0.16562283
A33: Total price appreciation | B33: ='PF Client 130K'!B53 -> 0.65508116 | C33: ='PF Client 130K'!C53 -> 0.83551241 | D33: ='PF Client 130K'!D53 -> 0.96659557 | E33: ='PF Alt 70 LTV'!B53 -> 0.65508116 | F33: ='PF Alt 70 LTV'!C53 -> 0.83551241 | G33: ='PF Alt 70 LTV'!D53 -> 0.96659557
A35: KEY TAKEAWAYS / FLAGS
A36: 1) Price ($270,000), size (2,016 SQFT), rent, NNN and 3.5% rent escalation are per client. Expense growth, expenses, rate, exit cap and closing costs are ASSUMPTIONS (yellow on Inputs) - lender information provided expected to change
A37: 2) Primary scenario: client's $130,000 down payment (about 43% down) with standard Central FL terms: 6.75% fixed, 25-yr amortization, 10-yr term. Alt scenario shows 70% LTV for comparison.
A38: 3) viewed DSCR line with the lender's 1.25x minimum; 'Max loan at lender min DSCR' shows the loan size the income supports.
A39: 4) Sale price = Year N+1 NOI / exit cap. Pre-tax: excludes depreciation, cap-gains, depreciation recapture and 1031 exchange effects.

Sheet PF Client 130K
A1: Client Scenario ($130K Down) -Pro Forma & Returns
A3: ANNUAL CASH FLOW
A4: Year | C4: 1 | D4: 2 | E4: 3 | F4: 4 | G4: 5 | H4: 6 | I4: 7 | J4: 8 | K4: 9 | L4: 10 | M4: 11
A6: Base rent | C6: =Inputs!$B$5*Inputs!$B$6*(1+Inputs!$B$8)^(C$4-1) -> 28224 | D6: =Inputs!$B$5*Inputs!$B$6*(1+Inputs!$B$8)^(D$4-1) -> 29211.84 | E6: =Inputs!$B$5*Inputs!$B$6*(1+Inputs!$B$8)^(E$4-1) -> 30234.254 | F6: =Inputs!$B$5*Inputs!$B$6*(1+Inputs!$B$8)^(F$4-1) -> 31292.453 | G6: =Inputs!$B$5*Inputs!$B$6*(1+Inputs!$B$8)^(G$4-1) -> 32387.689 | H6: =Inputs!$B$5*Inputs!$B$6*(1+Inputs!$B$8)^(H$4-1) -> 33521.258 | I6: =Inputs!$B$5*Inputs!$B$6*(1+Inputs!$B$8)^(I$4-1) -> 34694.502 | J6: =Inputs!$B$5*Inputs!$B$6*(1+Inputs!$B$8)^(J$4-1) -> 35908.81 | ... M6: =Inputs!$B$5*Inputs!$B$6*(1+Inputs!$B$8)^(M$4-1) -> 39812.739
A7: Less: vacancy / credit loss | C7: =-C6*Inputs!$B$10 -> -846.72 | D7: =-D6*Inputs!$B$10 -> -876.3552 | E7: =-E6*Inputs!$B$10 -> -907.02763 | F7: =-F6*Inputs!$B$10 -> -938.7736 | G7: =-G6*Inputs!$B$10 -> -971.63068 | H7: =-H6*Inputs!$B$10 -> -1005.6377 | I7: =-I6*Inputs!$B$10 -> -1040.8351 | J7: =-J6*Inputs!$B$10 -> -1077.2643 | ... M7: =-M6*Inputs!$B$10 -> -1194.3822
A8: NNN reimbursements | C8: =Inputs!$B$5*Inputs!$B$7*(1+Inputs!$B$9)^(C$4-1)*Inputs!$B$11 -> 9072 | D8: =Inputs!$B$5*Inputs!$B$7*(1+Inputs!$B$9)^(D$4-1)*Inputs!$B$11 -> 9344.16 | E8: =Inputs!$B$5*Inputs!$B$7*(1+Inputs!$B$9)^(E$4-1)*Inputs!$B$11 -> 9624.4848 | F8: =Inputs!$B$5*Inputs!$B$7*(1+Inputs!$B$9)^(F$4-1)*Inputs!$B$11 -> 9913.2193 | G8: =Inputs!$B$5*Inputs!$B$7*(1+Inputs!$B$9)^(G$4-1)*Inputs!$B$11 -> 10210.616 | H8: =Inputs!$B$5*Inputs!$B$7*(1+Inputs!$B$9)^(H$4-1)*Inputs!$B$11 -> 10516.934 | I8: =Inputs!$B$5*Inputs!$B$7*(1+Inputs!$B$9)^(I$4-1)*Inputs!$B$11 -> 10832.442 | J8: =Inputs!$B$5*Inputs!$B$7*(1+Inputs!$B$9)^(J$4-1)*Inputs!$B$11 -> 11157.416 | ... M8: =Inputs!$B$5*Inputs!$B$7*(1+Inputs!$B$9)^(M$4-1)*Inputs!$B$11 -> 12192.009
A9: Effective gross income | C9: =SUM(C6:C8) -> 36449.28 | D9: =SUM(D6:D8) -> 37679.645 | E9: =SUM(E6:E8) -> 38951.712 | F9: =SUM(F6:F8) -> 40266.899 | G9: =SUM(G6:G8) -> 41626.674 | H9: =SUM(H6:H8) -> 43032.555 | I9: =SUM(I6:I8) -> 44486.11 | J9: =SUM(J6:J8) -> 45988.961 | ... M9: =SUM(M6:M8) -> 50810.367
A11: NNN operating expenses (taxes, ins., CAM) | C11: =-Inputs!$B$5*Inputs!$B$7*(1+Inputs!$B$9)^(C$4-1) -> -9072 | D11: =-Inputs!$B$5*Inputs!$B$7*(1+Inputs!$B$9)^(D$4-1) -> -9344.16 | E11: =-Inputs!$B$5*Inputs!$B$7*(1+Inputs!$B$9)^(E$4-1) -> -9624.4848 | F11: =-Inputs!$B$5*Inputs!$B$7*(1+Inputs!$B$9)^(F$4-1) -> -9913.2193 | G11: =-Inputs!$B$5*Inputs!$B$7*(1+Inputs!$B$9)^(G$4-1) -> -10210.616 | H11: =-Inputs!$B$5*Inputs!$B$7*(1+Inputs!$B$9)^(H$4-1) -> -10516.934 | I11: =-Inputs!$B$5*Inputs!$B$7*(1+Inputs!$B$9)^(I$4-1) -> -10832.442 | J11: =-Inputs!$B$5*Inputs!$B$7*(1+Inputs!$B$9)^(J$4-1) -> -11157.416 | ... M11: =-Inputs!$B$5*Inputs!$B$7*(1+Inputs!$B$9)^(M$4-1) -> -12192.009
A12: Property management fee | C12: =-(C6+C7)*Inputs!$B$12 -> -547.5456 | D12: =-(D6+D7)*Inputs!$B$12 -> -566.7097 | E12: =-(E6+E7)*Inputs!$B$12 -> -586.54454 | F12: =-(F6+F7)*Inputs!$B$12 -> -607.07359 | G12: =-(G6+G7)*Inputs!$B$12 -> -628.32117 | H12: =-(H6+H7)*Inputs!$B$12 -> -650.31241 | I12: =-(I6+I7)*Inputs!$B$12 -> -673.07335 | J12: =-(J6+J7)*Inputs!$B$12 -> -696.63091 | ... M12: =-(M6+M7)*Inputs!$B$12 -> -772.36714
A13: Non-recoverable expenses | C13: =-Inputs!$B$5*Inputs!$B$13*(1+Inputs!$B$9)^(C$4-1) -> -201.6 | D13: =-Inputs!$B$5*Inputs!$B$13*(1+Inputs!$B$9)^(D$4-1) -> -207.648 | E13: =-Inputs!$B$5*Inputs!$B$13*(1+Inputs!$B$9)^(E$4-1) -> -213.87744 | F13: =-Inputs!$B$5*Inputs!$B$13*(1+Inputs!$B$9)^(F$4-1) -> -220.29376 | G13: =-Inputs!$B$5*Inputs!$B$13*(1+Inputs!$B$9)^(G$4-1) -> -226.90258 | H13: =-Inputs!$B$5*Inputs!$B$13*(1+Inputs!$B$9)^(H$4-1) -> -233.70965 | I13: =-Inputs!$B$5*Inputs!$B$13*(1+Inputs!$B$9)^(I$4-1) -> -240.72094 | J13: =-Inputs!$B$5*Inputs!$B$13*(1+Inputs!$B$9)^(J$4-1) -> -247.94257 | ... M13: =-Inputs!$B$5*Inputs!$B$13*(1+Inputs!$B$9)^(M$4-1) -> -270.93354
A14: Capital / roof reserve | C14: =-Inputs!$B$5*Inputs!$B$14*(1+Inputs!$B$9)^(C$4-1) -> -302.4 | D14: =-Inputs!$B$5*Inputs!$B$14*(1+Inputs!$B$9)^(D$4-1) -> -311.472 | E14: =-Inputs!$B$5*Inputs!$B$14*(1+Inputs!$B$9)^(E$4-1) -> -320.81616 | F14: =-Inputs!$B$5*Inputs!$B$14*(1+Inputs!$B$9)^(F$4-1) -> -330.44064 | G14: =-Inputs!$B$5*Inputs!$B$14*(1+Inputs!$B$9)^(G$4-1) -> -340.35386 | H14: =-Inputs!$B$5*Inputs!$B$14*(1+Inputs!$B$9)^(H$4-1) -> -350.56448 | I14: =-Inputs!$B$5*Inputs!$B$14*(1+Inputs!$B$9)^(I$4-1) -> -361.08141 | J14: =-Inputs!$B$5*Inputs!$B$14*(1+Inputs!$B$9)^(J$4-1) -> -371.91386 | ... M14: =-Inputs!$B$5*Inputs!$B$14*(1+Inputs!$B$9)^(M$4-1) -> -406.40031
A15: Total operating expenses | C15: =SUM(C11:C14) -> -10123.546 | D15: =SUM(D11:D14) -> -10429.99 | E15: =SUM(E11:E14) -> -10745.723 | F15: =SUM(F11:F14) -> -11071.027 | G15: =SUM(G11:G14) -> -11406.194 | H15: =SUM(H11:H14) -> -11751.521 | I15: =SUM(I11:I14) -> -12107.318 | J15: =SUM(J11:J14) -> -12473.903 | ... M15: =SUM(M11:M14) -> -13641.71
A16: Net operating income (NOI) | C16: =C9+C15 -> 26325.734 | D16: =D9+D15 -> 27249.655 | E16: =E9+E15 -> 28205.989 | F16: =F9+F15 -> 29195.872 | G16: =G9+G15 -> 30220.481 | H16: =H9+H15 -> 31281.034 | I16: =I9+I15 -> 32378.792 | J16: =J9+J15 -> 33515.058 | ... M16: =M9+M15 -> 37168.656
A18: Annual debt service | C18: =-$B$35 -> -11607.314 | D18: =-$B$35 -> -11607.314 | E18: =-$B$35 -> -11607.314 | F18: =-$B$35 -> -11607.314 | G18: =-$B$35 -> -11607.314 | H18: =-$B$35 -> -11607.314 | I18: =-$B$35 -> -11607.314 | J18: =-$B$35 -> -11607.314 | ... L18: =-$B$35 -> -11607.314
A19: Loan balance (end of year) | C19: =FV(Inputs!$B$22/12,12*C$4,$B$34,-$B$32) -> 137774.68 | D19: =FV(Inputs!$B$22/12,12*D$4,$B$34,-$B$32) -> 135394.41 | E19: =FV(Inputs!$B$22/12,12*E$4,$B$34,-$B$32) -> 132848.41 | F19: =FV(Inputs!$B$22/12,12*F$4,$B$34,-$B$32) -> 130125.14 | G19: =FV(Inputs!$B$22/12,12*G$4,$B$34,-$B$32) -> 127212.25 | H19: =FV(Inputs!$B$22/12,12*H$4,$B$34,-$B$32) -> 124096.54 | I19: =FV(Inputs!$B$22/12,12*I$4,$B$34,-$B$32) -> 120763.89 | J19: =FV(Inputs!$B$22/12,12*J$4,$B$34,-$B$32) -> 117199.2 | ... L19: =FV(Inputs!$B$22/12,12*L$4,$B$34,-$B$32) -> 109307.92
A20: Principal paid | C20: =$B$32-C19 -> 2225.3229 | D20: =C19-D19 -> 2380.2675 | E20: =D19-E19 -> 2546.0007 | F20: =E19-F19 -> 2723.2734 | G20: =F19-G19 -> 2912.8893 | H20: =G19-H19 -> 3115.7078 | I20: =H19-I19 -> 3332.6481 | J20: =I19-J19 -> 3564.6935 | K20: =J19-K19 -> 3812.8958 | L20: =K19-L19 -> 4078.3799
A21: Interest paid | C21: =-C18-C20 -> 9381.9907 | D21: =-D18-D20 -> 9227.0461 | E21: =-E18-E20 -> 9061.313 | F21: =-F18-F20 -> 8884.0402 | G21: =-G18-G20 -> 8694.4243 | H21: =-H18-H20 -> 8491.6058 | I21: =-I18-I20 -> 8274.6655 | J21: =-J18-J20 -> 8042.6201 | ... L21: =-L18-L20 -> 7528.9338
A22: Debt service coverage ratio (DSCR) | C22: =IFERROR(C16/-C18,0) -> 2.2680299 | D22: =IFERROR(D16/-D18,0) -> 2.3476281 | E22: =IFERROR(E16/-E18,0) -> 2.4300187 | F22: =IFERROR(F16/-F18,0) -> 2.5152996 | G22: =IFERROR(G16/-G18,0) -> 2.6035724 | H22: =IFERROR(H16/-H18,0) -> 2.6949417 | I22: =IFERROR(I16/-I18,0) -> 2.7895164 | J22: =IFERROR(J16/-J18,0) -> 2.8874087 | ... L22: =IFERROR(L16/-L18,0) -> 3.0936158
A23: Cash flow after debt service (pre-tax) | C23: =C16+C18 -> 14718.421 | D23: =D16+D18 -> 15642.341 | E23: =E16+E18 -> 16598.675 | F23: =F16+F18 -> 17588.558 | G23: =G16+G18 -> 18613.167 | H23: =H16+H18 -> 19673.72 | I23: =I16+I18 -> 20771.478 | J23: =J16+J18 -> 21907.745 | ... L23: =L16+L18 -> 24301.255
A24: Cash-on-cash return | C24: =IFERROR(C23/$B$33,0) -> 0.10479474 | D24: =IFERROR(D23/$B$33,0) -> 0.11137303 | E24: =IFERROR(E23/$B$33,0) -> 0.11818209 | F24: =IFERROR(F23/$B$33,0) -> 0.12523003 | G24: =IFERROR(G23/$B$33,0) -> 0.13252522 | H24: =IFERROR(H23/$B$33,0) -> 0.14007633 | I24: =IFERROR(I23/$B$33,0) -> 0.14789233 | J24: =IFERROR(J23/$B$33,0) -> 0.15598252 | ... L24: =IFERROR(L23/$B$33,0) -> 0.17302424
A27: ACQUISITION, FINANCING & EQUITY
A28: Purchase price | B28: =Inputs!$B$4 -> 270000
A29: Closing costs | B29: =B28*Inputs!$B$15 -> 4050
A30: Loan origination & lender costs | B30: =B32*Inputs!$B$25+Inputs!$B$26 -> 6400
A31: Total uses of funds | B31: =SUM(B28:B30) -> 280450
A32: Loan amount | B32: =Inputs!$B$21 -> 140000
A33: Total equity required (cash to close) | B33: =B31-B32 -> 140450
A34: Monthly payment (P&I) | B34: =PMT(Inputs!$B$22/12,Inputs!$B$23*12,-B32) -> 967.27614
A35: Annual debt service | B35: =B34*12 -> 11607.314
A36: Going-in cap rate (Yr-1 NOI / price) | B36: =C16/B28 -> 0.09750272
A37: Loan-to-value | B37: =B32/B28 -> 0.51851852
A38: Max loan supported at lender min DSCR | B38: =PV(Inputs!$B$22/12,Inputs!$B$23*12,-(C16/Inputs!$B$27)/12) -> 254019.35
A39: Max LTV supported at lender min DSCR | B39: =B38/B28 -> 0.9408124
A41: SALE ANALYSIS BY HOLD PERIOD
A42: Hold period | B42: =Inputs!$B$32 -> 5 | C42: =Inputs!$B$33 -> 8 | D42: =Inputs!$B$34 -> 10
A43: Forward NOI (Year N+1) | B43: =INDEX($C$16:$M$16,B$42+1) -> 31281.034 | C43: =INDEX($C$16:$M$16,C$42+1) -> 34691.185 | D43: =INDEX($C$16:$M$16,D$42+1) -> 37168.656
A44: Gross sale price (Fwd NOI / exit cap) | B44: =B43/Inputs!$B$30 -> 446871.91 | C44: =C43/Inputs!$B$30 -> 495588.35 | D44: =D43/Inputs!$B$30 -> 530980.8
A45: Less: selling costs | B45: =-B44*Inputs!$B$31 -> -15640.517 | C45: =-C44*Inputs!$B$31 -> -17345.592 | D45: =-D44*Inputs!$B$31 -> -18584.328
A46: Less: loan payoff | B46: =-INDEX($C$19:$L$19,B$42) -> -127212.25 | C46: =-INDEX($C$19:$L$19,C$42) -> -117199.2 | D46: =-INDEX($C$19:$L$19,D$42) -> -109307.92
A47: Net sale proceeds to equity | B47: =SUM(B44:B46) -> 304019.15 | C47: =SUM(C44:C46) -> 361043.56 | D47: =SUM(D44:D46) -> 403088.55
...

Sheet PF Alt 70 LTV
A1: Alternative Scenario (70% LTV) - 11-Year Pro Forma & Returns
A3: ANNUAL CASH FLOW
A4: Year | C4: 1 | D4: 2 | E4: 3 | F4: 4 | G4: 5 | H4: 6 | I4: 7 | J4: 8 | K4: 9 | L4: 10 | M4: 11
A6: Base rent | C6: =Inputs!$B$5*Inputs!$B$6*(1+Inputs!$B$8)^(C$4-1) -> 28224 | D6: =Inputs!$B$5*Inputs!$B$6*(1+Inputs!$B$8)^(D$4-1) -> 29211.84 | E6: =Inputs!$B$5*Inputs!$B$6*(1+Inputs!$B$8)^(E$4-1) -> 30234.254 | F6: =Inputs!$B$5*Inputs!$B$6*(1+Inputs!$B$8)^(F$4-1) -> 31292.453 | G6: =Inputs!$B$5*Inputs!$B$6*(1+Inputs!$B$8)^(G$4-1) -> 32387.689 | H6: =Inputs!$B$5*Inputs!$B$6*(1+Inputs!$B$8)^(H$4-1) -> 33521.258 | I6: =Inputs!$B$5*Inputs!$B$6*(1+Inputs!$B$8)^(I$4-1) -> 34694.502 | J6: =Inputs!$B$5*Inputs!$B$6*(1+Inputs!$B$8)^(J$4-1) -> 35908.81 | ... M6: =Inputs!$B$5*Inputs!$B$6*(1+Inputs!$B$8)^(M$4-1) -> 39812.739
A7: Less: vacancy / credit loss | C7: =-C6*Inputs!$B$10 -> -846.72 | D7: =-D6*Inputs!$B$10 -> -876.3552 | E7: =-E6*Inputs!$B$10 -> -907.02763 | F7: =-F6*Inputs!$B$10 -> -938.7736 | G7: =-G6*Inputs!$B$10 -> -971.63068 | H7: =-H6*Inputs!$B$10 -> -1005.6377 | I7: =-I6*Inputs!$B$10 -> -1040.8351 | J7: =-J6*Inputs!$B$10 -> -1077.2643 | ... M7: =-M6*Inputs!$B$10 -> -1194.3822
A8: NNN reimbursements | C8: =Inputs!$B$5*Inputs!$B$7*(1+Inputs!$B$9)^(C$4-1)*Inputs!$B$11 -> 9072 | D8: =Inputs!$B$5*Inputs!$B$7*(1+Inputs!$B$9)^(D$4-1)*Inputs!$B$11 -> 9344.16 | E8: =Inputs!$B$5*Inputs!$B$7*(1+Inputs!$B$9)^(E$4-1)*Inputs!$B$11 -> 9624.4848 | F8: =Inputs!$B$5*Inputs!$B$7*(1+Inputs!$B$9)^(F$4-1)*Inputs!$B$11 -> 9913.2193 | G8: =Inputs!$B$5*Inputs!$B$7*(1+Inputs!$B$9)^(G$4-1)*Inputs!$B$11 -> 10210.616 | H8: =Inputs!$B$5*Inputs!$B$7*(1+Inputs!$B$9)^(H$4-1)*Inputs!$B$11 -> 10516.934 | I8: =Inputs!$B$5*Inputs!$B$7*(1+Inputs!$B$9)^(I$4-1)*Inputs!$B$11 -> 10832.442 | J8: =Inputs!$B$5*Inputs!$B$7*(1+Inputs!$B$9)^(J$4-1)*Inputs!$B$11 -> 11157.416 | ... M8: =Inputs!$B$5*Inputs!$B$7*(1+Inputs!$B$9)^(M$4-1)*Inputs!$B$11 -> 12192.009
A9: Effective gross income | C9: =SUM(C6:C8) -> 36449.28 | D9: =SUM(D6:D8) -> 37679.645 | E9: =SUM(E6:E8) -> 38951.712 | F9: =SUM(F6:F8) -> 40266.899 | G9: =SUM(G6:G8) -> 41626.674 | H9: =SUM(H6:H8) -> 43032.555 | I9: =SUM(I6:I8) -> 44486.11 | J9: =SUM(J6:J8) -> 45988.961 | ... M9: =SUM(M6:M8) -> 50810.367
A11: NNN operating expenses (taxes, ins., CAM) | C11: =-Inputs!$B$5*Inputs!$B$7*(1+Inputs!$B$9)^(C$4-1) -> -9072 | D11: =-Inputs!$B$5*Inputs!$B$7*(1+Inputs!$B$9)^(D$4-1) -> -9344.16 | E11: =-Inputs!$B$5*Inputs!$B$7*(1+Inputs!$B$9)^(E$4-1) -> -9624.4848 | F11: =-Inputs!$B$5*Inputs!$B$7*(1+Inputs!$B$9)^(F$4-1) -> -9913.2193 | G11: =-Inputs!$B$5*Inputs!$B$7*(1+Inputs!$B$9)^(G$4-1) -> -10210.616 | H11: =-Inputs!$B$5*Inputs!$B$7*(1+Inputs!$B$9)^(H$4-1) -> -10516.934 | I11: =-Inputs!$B$5*Inputs!$B$7*(1+Inputs!$B$9)^(I$4-1) -> -10832.442 | J11: =-Inputs!$B$5*Inputs!$B$7*(1+Inputs!$B$9)^(J$4-1) -> -11157.416 | ... M11: =-Inputs!$B$5*Inputs!$B$7*(1+Inputs!$B$9)^(M$4-1) -> -12192.009
A12: Property management fee | C12: =-(C6+C7)*Inputs!$B$12 -> -547.5456 | D12: =-(D6+D7)*Inputs!$B$12 -> -566.7097 | E12: =-(E6+E7)*Inputs!$B$12 -> -586.54454 | F12: =-(F6+F7)*Inputs!$B$12 -> -607.07359 | G12: =-(G6+G7)*Inputs!$B$12 -> -628.32117 | H12: =-(H6+H7)*Inputs!$B$12 -> -650.31241 | I12: =-(I6+I7)*Inputs!$B$12 -> -673.07335 | J12: =-(J6+J7)*Inputs!$B$12 -> -696.63091 | ... M12: =-(M6+M7)*Inputs!$B$12 -> -772.36714
A13: Non-recoverable expenses | C13: =-Inputs!$B$5*Inputs!$B$13*(1+Inputs!$B$9)^(C$4-1) -> -201.6 | D13: =-Inputs!$B$5*Inputs!$B$13*(1+Inputs!$B$9)^(D$4-1) -> -207.648 | E13: =-Inputs!$B$5*Inputs!$B$13*(1+Inputs!$B$9)^(E$4-1) -> -213.87744 | F13: =-Inputs!$B$5*Inputs!$B$13*(1+Inputs!$B$9)^(F$4-1) -> -220.29376 | G13: =-Inputs!$B$5*Inputs!$B$13*(1+Inputs!$B$9)^(G$4-1) -> -226.90258 | H13: =-Inputs!$B$5*Inputs!$B$13*(1+Inputs!$B$9)^(H$4-1) -> -233.70965 | I13: =-Inputs!$B$5*Inputs!$B$13*(1+Inputs!$B$9)^(I$4-1) -> -240.72094 | J13: =-Inputs!$B$5*Inputs!$B$13*(1+Inputs!$B$9)^(J$4-1) -> -247.94257 | ... M13: =-Inputs!$B$5*Inputs!$B$13*(1+Inputs!$B$9)^(M$4-1) -> -270.93354
A14: Capital / roof reserve | C14: =-Inputs!$B$5*Inputs!$B$14*(1+Inputs!$B$9)^(C$4-1) -> -302.4 | D14: =-Inputs!$B$5*Inputs!$B$14*(1+Inputs!$B$9)^(D$4-1) -> -311.472 | E14: =-Inputs!$B$5*Inputs!$B$14*(1+Inputs!$B$9)^(E$4-1) -> -320.81616 | F14: =-Inputs!$B$5*Inputs!$B$14*(1+Inputs!$B$9)^(F$4-1) -> -330.44064 | G14: =-Inputs!$B$5*Inputs!$B$14*(1+Inputs!$B$9)^(G$4-1) -> -340.35386 | H14: =-Inputs!$B$5*Inputs!$B$14*(1+Inputs!$B$9)^(H$4-1) -> -350.56448 | I14: =-Inputs!$B$5*Inputs!$B$14*(1+Inputs!$B$9)^(I$4-1) -> -361.08141 | J14: =-Inputs!$B$5*Inputs!$B$14*(1+Inputs!$B$9)^(J$4-1) -> -371.91386 | ... M14: =-Inputs!$B$5*Inputs!$B$14*(1+Inputs!$B$9)^(M$4-1) -> -406.40031
A15: Total operating expenses | C15: =SUM(C11:C14) -> -10123.546 | D15: =SUM(D11:D14) -> -10429.99 | E15: =SUM(E11:E14) -> -10745.723 | F15: =SUM(F11:F14) -> -11071.027 | G15: =SUM(G11:G14) -> -11406.194 | H15: =SUM(H11:H14) -> -11751.521 | I15: =SUM(I11:I14) -> -12107.318 | J15: =SUM(J11:J14) -> -12473.903 | ... M15: =SUM(M11:M14) -> -13641.71
A16: Net operating income (NOI) | C16: =C9+C15 -> 26325.734 | D16: =D9+D15 -> 27249.655 | E16: =E9+E15 -> 28205.989 | F16: =F9+F15 -> 29195.872 | G16: =G9+G15 -> 30220.481 | H16: =H9+H15 -> 31281.034 | I16: =I9+I15 -> 32378.792 | J16: =J9+J15 -> 33515.058 | ... M16: =M9+M15 -> 37168.656
A18: Annual debt service | C18: =-$B$35 -> -15669.873 | D18: =-$B$35 -> -15669.873 | E18: =-$B$35 -> -15669.873 | F18: =-$B$35 -> -15669.873 | G18: =-$B$35 -> -15669.873 | H18: =-$B$35 -> -15669.873 | I18: =-$B$35 -> -15669.873 | J18: =-$B$35 -> -15669.873 | ... L18: =-$B$35 -> -15669.873
A19: Loan balance (end of year) | C19: =FV(Inputs!$C$22/12,12*C$4,$B$34,-$B$32) -> 185995.81 | D19: =FV(Inputs!$C$22/12,12*D$4,$B$34,-$B$32) -> 182782.45 | E19: =FV(Inputs!$C$22/12,12*E$4,$B$34,-$B$32) -> 179345.35 | F19: =FV(Inputs!$C$22/12,12*F$4,$B$34,-$B$32) -> 175668.93 | G19: =FV(Inputs!$C$22/12,12*G$4,$B$34,-$B$32) -> 171736.53 | H19: =FV(Inputs!$C$22/12,12*H$4,$B$34,-$B$32) -> 167530.33 | I19: =FV(Inputs!$C$22/12,12*I$4,$B$34,-$B$32) -> 163031.25 | J19: =FV(Inputs!$C$22/12,12*J$4,$B$34,-$B$32) -> 158218.92 | ... L19: =FV(Inputs!$C$22/12,12*L$4,$B$34,-$B$32) -> 147565.69
A20: Principal paid | C20: =$B$32-C19 -> 3004.1859 | D20: =C19-D19 -> 3213.3612 | E20: =D19-E19 -> 3437.1009 | F20: =E19-F19 -> 3676.4191 | G20: =F19-G19 -> 3932.4006 | H20: =G19-H19 -> 4206.2056 | I20: =H19-I19 -> 4499.075 | J20: =I19-J19 -> 4812.3363 | K20: =J19-K19 -> 5147.4093 | L20: =K19-L19 -> 5505.8128
A21: Interest paid | C21: =-C18-C20 -> 12665.687 | D21: =-D18-D20 -> 12456.512 | E21: =-E18-E20 -> 12232.772 | F21: =-F18-F20 -> 11993.454 | G21: =-G18-G20 -> 11737.473 | H21: =-H18-H20 -> 11463.668 | I21: =-I18-I20 -> 11170.798 | J21: =-J18-J20 -> 10857.537 | ... L21: =-L18-L20 -> 10164.061
A22: Debt service coverage ratio (DSCR) | C22: =IFERROR(C16/-C18,0) -> 1.6800222 | D22: =IFERROR(D16/-D18,0) -> 1.7389837 | E22: =IFERROR(E16/-E18,0) -> 1.8000138 | F22: =IFERROR(F16/-F18,0) -> 1.8631849 | G22: =IFERROR(G16/-G18,0) -> 1.9285721 | H22: =IFERROR(H16/-H18,0) -> 1.9962531 | I22: =IFERROR(I16/-I18,0) -> 2.0663084 | J22: =IFERROR(J16/-J18,0) -> 2.1388213 | ... L22: =IFERROR(L16/-L18,0) -> 2.2915672
A23: Cash flow after debt service (pre-tax) | C23: =C16+C18 -> 10655.861 | D23: =D16+D18 -> 11579.782 | E23: =E16+E18 -> 12536.115 | F23: =F16+F18 -> 13525.998 | G23: =G16+G18 -> 14550.607 | H23: =H16+H18 -> 15611.161 | I23: =I16+I18 -> 16708.918 | J23: =J16+J18 -> 17845.185 | ... L23: =L16+L18 -> 20238.695
A24: Cash-on-cash return | C24: =IFERROR(C23/$B$33,0) -> 0.11590016 | D24: =IFERROR(D23/$B$33,0) -> 0.12594933 | E24: =IFERROR(E23/$B$33,0) -> 0.13635105 | F24: =IFERROR(F23/$B$33,0) -> 0.14711767 | G24: =IFERROR(G23/$B$33,0) -> 0.15826199 | H24: =IFERROR(H23/$B$33,0) -> 0.16979727 | I24: =IFERROR(I23/$B$33,0) -> 0.1817372 | J24: =IFERROR(J23/$B$33,0) -> 0.19409599 | ... L24: =IFERROR(L23/$B$33,0) -> 0.22012938
A27: ACQUISITION, FINANCING & EQUITY
A28: Purchase price | B28: =Inputs!$B$4 -> 270000
A29: Closing costs | B29: =B28*Inputs!$B$15 -> 4050
A30: Loan origination & lender costs | B30: =B32*Inputs!$C$25+Inputs!$C$26 -> 6890
A31: Total uses of funds | B31: =SUM(B28:B30) -> 280940
A32: Loan amount | B32: =Inputs!$C$21 -> 189000
A33: Total equity required (cash to close) | B33: =B31-B32 -> 91940
A34: Monthly payment (P&I) | B34: =PMT(Inputs!$C$22/12,Inputs!$C$23*12,-B32) -> 1305.8228
A35: Annual debt service | B35: =B34*12 -> 15669.873
A36: Going-in cap rate (Yr-1 NOI / price) | B36: =C16/B28 -> 0.09750272
A37: Loan-to-value | B37: =B32/B28 -> 0.7
A38: Max loan supported at lender min DSCR | B38: =PV(Inputs!$C$22/12,Inputs!$C$23*12,-(C16/Inputs!$C$27)/12) -> 254019.35
A39: Max LTV supported at lender min DSCR | B39: =B38/B28 -> 0.9408124
A41: SALE ANALYSIS BY HOLD PERIOD
A42: Hold period | B42: =Inputs!$B$32 -> 5 | C42: =Inputs!$B$33 -> 8 | D42: =Inputs!$B$34 -> 10
A43: Forward NOI (Year N+1) | B43: =INDEX($C$16:$M$16,B$42+1) -> 31281.034 | C43: =INDEX($C$16:$M$16,C$42+1) -> 34691.185 | D43: =INDEX($C$16:$M$16,D$42+1) -> 37168.656
A44: Gross sale price (Fwd NOI / exit cap) | B44: =B43/Inputs!$B$30 -> 446871.91 | C44: =C43/Inputs!$B$30 -> 495588.35 | D44: =D43/Inputs!$B$30 -> 530980.8
A45: Less: selling costs | B45: =-B44*Inputs!$B$31 -> -15640.517 | C45: =-C44*Inputs!$B$31 -> -17345.592 | D45: =-D44*Inputs!$B$31 -> -18584.328
A46: Less: loan payoff | B46: =-INDEX($C$19:$L$19,B$42) -> -171736.53 | C46: =-INDEX($C$19:$L$19,C$42) -> -158218.92 | D46: =-INDEX($C$19:$L$19,D$42) -> -147565.69
A47: Net sale proceeds to equity | B47: =SUM(B44:B46) -> 259494.87 | C47: =SUM(C44:C46) -> 320023.84 | D47: =SUM(D44:D46) -> 364830.78
...

Sheet Rent Schedule
A1: Hypothetical Lease Rent Schedule - for a 3-Year min NNN Lease
A2: Blue = lease input | Green = linked from Inputs tab | Black = formula | Yellow fill = assumption. Any changes must be made on assumptions tab
A4: LEASE TERMS
A5: Building size (SF) | B5: =Inputs!B5 -> 2016 | C5: Inputs tab
A6: Base rent ($/SF/yr, Year 1) | B6: =Inputs!B6 -> 14 | C6: Inputs tab
A7: NNN charges ($/SF/yr, Year 1) | B7: =Inputs!B7 -> 4.5 | C7: Inputs tab
A8: Annual base rent escalation | B8: =Inputs!B8 -> 0.035 | C8: Inputs tab; applied each lease anniversary
A9: Annual NNN expense growth | B9: =Inputs!B9 -> 0.03 | C9: Inputs tab; applied each lease anniversary
A10: Lease start date | B10: 46388 | C10: ASSUMPTION
A11: Lease term (months) | B11: 36 | C11: Per client: 3 years (schedule supports up to 36 months)
A12: Free rent / abatement (months) | B12: 1 | C12: Per client: 1 month free, applied to the first month(s) of the term
A13: NNN also abated during free months? (1 = yes, 0 = no) | B13: 0 | C13: ASSUMPTION - 0 = tenant still pays NNN charges during free rent
A14: Tenant improvement allowance ($) | B14: 0 | C14: Per client: none
A16: MONTHLY RENT SCHEDULE
A17: Month | B17: Date | C17: Lease Year | D17: Base Rent $/SF/yr | E17: Scheduled Base Rent | F17: Rent Abatement | G17: Net Base Rent | H17: NNN $/SF/yr | I17: NNN Charges | J17: NNN Abatement | K17: Net NNN | L17: Total Due from Tenant | M17: Cumulative Cash Received
A18: 1 | B18: =EDATE($B$10,A18-1) -> 46388 | C18: =ROUNDUP(A18/12,0) -> 1 | D18: =$B$6*(1+$B$8)^(C18-1) -> 14 | E18: =IF(A18>$B$11,0,D18*$B$5/12) -> 2352 | F18: =-IF(A18<=$B$12,E18,0) -> -2352 | G18: =E18+F18 -> 0 | H18: =$B$7*(1+$B$9)^(C18-1) -> 4.5 | I18: =IF(A18>$B$11,0,H18*$B$5/12) -> 756 | J18: =-IF(AND($B$13=1,A18<=$B$12),I18,0) -> 0 | K18: =I18+J18 -> 756 | L18: =G18+K18 -> 756 | M18: =SUM($L$18:L18) -> 756
A19: 2 | B19: =EDATE($B$10,A19-1) -> 46419 | C19: =ROUNDUP(A19/12,0) -> 1 | D19: =$B$6*(1+$B$8)^(C19-1) -> 14 | E19: =IF(A19>$B$11,0,D19*$B$5/12) -> 2352 | F19: =-IF(A19<=$B$12,E19,0) -> 0 | G19: =E19+F19 -> 2352 | H19: =$B$7*(1+$B$9)^(C19-1) -> 4.5 | I19: =IF(A19>$B$11,0,H19*$B$5/12) -> 756 | J19: =-IF(AND($B$13=1,A19<=$B$12),I19,0) -> 0 | K19: =I19+J19 -> 756 | L19: =G19+K19 -> 3108 | M19: =SUM($L$18:L19) -> 3864
A20: 3 | B20: =EDATE($B$10,A20-1) -> 46447 | C20: =ROUNDUP(A20/12,0) -> 1 | D20: =$B$6*(1+$B$8)^(C20-1) -> 14 | E20: =IF(A20>$B$11,0,D20*$B$5/12) -> 2352 | F20: =-IF(A20<=$B$12,E20,0) -> 0 | G20: =E20+F20 -> 2352 | H20: =$B$7*(1+$B$9)^(C20-1) -> 4.5 | I20: =IF(A20>$B$11,0,H20*$B$5/12) -> 756 | J20: =-IF(AND($B$13=1,A20<=$B$12),I20,0) -> 0 | K20: =I20+J20 -> 756 | L20: =G20+K20 -> 3108 | M20: =SUM($L$18:L20) -> 6972
A21: 4 | B21: =EDATE($B$10,A21-1) -> 46478 | C21: =ROUNDUP(A21/12,0) -> 1 | D21: =$B$6*(1+$B$8)^(C21-1) -> 14 | E21: =IF(A21>$B$11,0,D21*$B$5/12) -> 2352 | F21: =-IF(A21<=$B$12,E21,0) -> 0 | G21: =E21+F21 -> 2352 | H21: =$B$7*(1+$B$9)^(C21-1) -> 4.5 | I21: =IF(A21>$B$11,0,H21*$B$5/12) -> 756 | J21: =-IF(AND($B$13=1,A21<=$B$12),I21,0) -> 0 | K21: =I21+J21 -> 756 | L21: =G21+K21 -> 3108 | M21: =SUM($L$18:L21) -> 10080
A22: 5 | B22: =EDATE($B$10,A22-1) -> 46508 | C22: =ROUNDUP(A22/12,0) -> 1 | D22: =$B$6*(1+$B$8)^(C22-1) -> 14 | E22: =IF(A22>$B$11,0,D22*$B$5/12) -> 2352 | F22: =-IF(A22<=$B$12,E22,0) -> 0 | G22: =E22+F22 -> 2352 | H22: =$B$7*(1+$B$9)^(C22-1) -> 4.5 | I22: =IF(A22>$B$11,0,H22*$B$5/12) -> 756 | J22: =-IF(AND($B$13=1,A22<=$B$12),I22,0) -> 0 | K22: =I22+J22 -> 756 | L22: =G22+K22 -> 3108 | M22: =SUM($L$18:L22) -> 13188
A23: 6 | B23: =EDATE($B$10,A23-1) -> 46539 | C23: =ROUNDUP(A23/12,0) -> 1 | D23: =$B$6*(1+$B$8)^(C23-1) -> 14 | E23: =IF(A23>$B$11,0,D23*$B$5/12) -> 2352 | F23: =-IF(A23<=$B$12,E23,0) -> 0 | G23: =E23+F23 -> 2352 | H23: =$B$7*(1+$B$9)^(C23-1) -> 4.5 | I23: =IF(A23>$B$11,0,H23*$B$5/12) -> 756 | J23: =-IF(AND($B$13=1,A23<=$B$12),I23,0) -> 0 | K23: =I23+J23 -> 756 | L23: =G23+K23 -> 3108 | M23: =SUM($L$18:L23) -> 16296
A24: 7 | B24: =EDATE($B$10,A24-1) -> 46569 | C24: =ROUNDUP(A24/12,0) -> 1 | D24: =$B$6*(1+$B$8)^(C24-1) -> 14 | E24: =IF(A24>$B$11,0,D24*$B$5/12) -> 2352 | F24: =-IF(A24<=$B$12,E24,0) -> 0 | G24: =E24+F24 -> 2352 | H24: =$B$7*(1+$B$9)^(C24-1) -> 4.5 | I24: =IF(A24>$B$11,0,H24*$B$5/12) -> 756 | J24: =-IF(AND($B$13=1,A24<=$B$12),I24,0) -> 0 | K24: =I24+J24 -> 756 | L24: =G24+K24 -> 3108 | M24: =SUM($L$18:L24) -> 19404
A25: 8 | B25: =EDATE($B$10,A25-1) -> 46600 | C25: =ROUNDUP(A25/12,0) -> 1 | D25: =$B$6*(1+$B$8)^(C25-1) -> 14 | E25: =IF(A25>$B$11,0,D25*$B$5/12) -> 2352 | F25: =-IF(A25<=$B$12,E25,0) -> 0 | G25: =E25+F25 -> 2352 | H25: =$B$7*(1+$B$9)^(C25-1) -> 4.5 | I25: =IF(A25>$B$11,0,H25*$B$5/12) -> 756 | J25: =-IF(AND($B$13=1,A25<=$B$12),I25,0) -> 0 | K25: =I25+J25 -> 756 | L25: =G25+K25 -> 3108 | M25: =SUM($L$18:L25) -> 22512
A26: 9 | B26: =EDATE($B$10,A26-1) -> 46631 | C26: =ROUNDUP(A26/12,0) -> 1 | D26: =$B$6*(1+$B$8)^(C26-1) -> 14 | E26: =IF(A26>$B$11,0,D26*$B$5/12) -> 2352 | F26: =-IF(A26<=$B$12,E26,0) -> 0 | G26: =E26+F26 -> 2352 | H26: =$B$7*(1+$B$9)^(C26-1) -> 4.5 | I26: =IF(A26>$B$11,0,H26*$B$5/12) -> 756 | J26: =-IF(AND($B$13=1,A26<=$B$12),I26,0) -> 0 | K26: =I26+J26 -> 756 | L26: =G26+K26 -> 3108 | M26: =SUM($L$18:L26) -> 25620
A27: 10 | B27: =EDATE($B$10,A27-1) -> 46661 | C27: =ROUNDUP(A27/12,0) -> 1 | D27: =$B$6*(1+$B$8)^(C27-1) -> 14 | E27: =IF(A27>$B$11,0,D27*$B$5/12) -> 2352 | F27: =-IF(A27<=$B$12,E27,0) -> 0 | G27: =E27+F27 -> 2352 | H27: =$B$7*(1+$B$9)^(C27-1) -> 4.5 | I27: =IF(A27>$B$11,0,H27*$B$5/12) -> 756 | J27: =-IF(AND($B$13=1,A27<=$B$12),I27,0) -> 0 | K27: =I27+J27 -> 756 | L27: =G27+K27 -> 3108 | M27: =SUM($L$18:L27) -> 28728
A28: 11 | B28: =EDATE($B$10,A28-1) -> 46692 | C28: =ROUNDUP(A28/12,0) -> 1 | D28: =$B$6*(1+$B$8)^(C28-1) -> 14 | E28: =IF(A28>$B$11,0,D28*$B$5/12) -> 2352 | F28: =-IF(A28<=$B$12,E28,0) -> 0 | G28: =E28+F28 -> 2352 | H28: =$B$7*(1+$B$9)^(C28-1) -> 4.5 | I28: =IF(A28>$B$11,0,H28*$B$5/12) -> 756 | J28: =-IF(AND($B$13=1,A28<=$B$12),I28,0) -> 0 | K28: =I28+J28 -> 756 | L28: =G28+K28 -> 3108 | M28: =SUM($L$18:L28) -> 31836
A29: 12 | B29: =EDATE($B$10,A29-1) -> 46722 | C29: =ROUNDUP(A29/12,0) -> 1 | D29: =$B$6*(1+$B$8)^(C29-1) -> 14 | E29: =IF(A29>$B$11,0,D29*$B$5/12) -> 2352 | F29: =-IF(A29<=$B$12,E29,0) -> 0 | G29: =E29+F29 -> 2352 | H29: =$B$7*(1+$B$9)^(C29-1) -> 4.5 | I29: =IF(A29>$B$11,0,H29*$B$5/12) -> 756 | J29: =-IF(AND($B$13=1,A29<=$B$12),I29,0) -> 0 | K29: =I29+J29 -> 756 | L29: =G29+K29 -> 3108 | M29: =SUM($L$18:L29) -> 34944
... A53: 36 | B53: =EDATE($B$10,A53-1) -> 47453 | C53: =ROUNDUP(A53/12,0) -> 3 | D53: =$B$6*(1+$B$8)^(C53-1) -> 14.99715 | E53: =IF(A53>$B$11,0,D53*$B$5/12) -> 2519.5212 | F53: =-IF(A53<=$B$12,E53,0) -> 0 | G53: =E53+F53 -> 2519.5212 | H53: =$B$7*(1+$B$9)^(C53-1) -> 4.77405 | I53: =IF(A53>$B$11,0,H53*$B$5/12) -> 802.0404 | J53: =-IF(AND($B$13=1,A53<=$B$12),I53,0) -> 0 | K53: =I53+J53 -> 802.0404 | L53: =G53+K53 -> 3321.5616 | M53: =SUM($L$18:L53) -> 113358.74
A54: Total | E54: =SUM(E18:E53) -> 87670.094 | F54: =SUM(F18:F53) -> -2352 | G54: =SUM(G18:G53) -> 85318.094 | I54: =SUM(I18:I53) -> 28040.645 | J54: =SUM(J18:J53) -> 0 | K54: =SUM(K18:K53) -> 28040.645 | L54: =SUM(L18:L53) -> 113358.74
A56: ANNUAL SUMMARY
A57: Lease Year | C57: Months | E57: Scheduled Base Rent | F57: Rent Abatement | G57: Net Base Rent | I57: NNN Charges (net) | L57: Total Due from Tenant | M57: Net Base Rent $/SF/yr
A58: 1 | C58: =COUNTIFS($C$18:$C$53,A58,$A$18:$A$53,"<="&$B$11) -> 12 | E58: =SUMIFS($E$18:$E$53,$C$18:$C$53,$A58) -> 28224 | F58: =SUMIFS($F$18:$F$53,$C$18:$C$53,$A58) -> -2352 | G58: =SUMIFS($G$18:$G$53,$C$18:$C$53,$A58) -> 25872 | I58: =SUMIFS($K$18:$K$53,$C$18:$C$53,$A58) -> 9072 | L58: =SUMIFS($L$18:$L$53,$C$18:$C$53,$A58) -> 34944 | M58: =IF(C58=0,0,G58/$B$5/(C58/12)) -> 12.833333
A59: 2 | C59: =COUNTIFS($C$18:$C$53,A59,$A$18:$A$53,"<="&$B$11) -> 12 | E59: =SUMIFS($E$18:$E$53,$C$18:$C$53,$A59) -> 29211.84 | F59: =SUMIFS($F$18:$F$53,$C$18:$C$53,$A59) -> 0 | G59: =SUMIFS($G$18:$G$53,$C$18:$C$53,$A59) -> 29211.84 | I59: =SUMIFS($K$18:$K$53,$C$18:$C$53,$A59) -> 9344.16 | L59: =SUMIFS($L$18:$L$53,$C$18:$C$53,$A59) -> 38556 | M59: =IF(C59=0,0,G59/$B$5/(C59/12)) -> 14.49
A60: 3 | C60: =COUNTIFS($C$18:$C$53,A60,$A$18:$A$53,"<="&$B$11) -> 12 | E60: =SUMIFS($E$18:$E$53,$C$18:$C$53,$A60) -> 30234.254 | F60: =SUMIFS($F$18:$F$53,$C$18:$C$53,$A60) -> 0 | G60: =SUMIFS($G$18:$G$53,$C$18:$C$53,$A60) -> 30234.254 | I60: =SUMIFS($K$18:$K$53,$C$18:$C$53,$A60) -> 9624.4848 | L60: =SUMIFS($L$18:$L$53,$C$18:$C$53,$A60) -> 39858.739 | M60: =IF(C60=0,0,G60/$B$5/(C60/12)) -> 14.99715
A61: Lease term total | C61: =SUM(C58:C60) -> 36 | E61: =SUM(E58:E60) -> 87670.094 | F61: =SUM(F58:F60) -> -2352 | G61: =SUM(G58:G60) -> 85318.094 | I61: =SUM(I58:I60) -> 28040.645 | L61: =SUM(L58:L60) -> 113358.74 | M61: =IF(C61=0,0,G61/$B$5/(C61/12)) -> 14.106828
A63: KEY LEASE METRICS
A64: Average net base rent over term ($/SF/yr) | B64: =M61 -> 14.106828 | C64: Effective rent after free-rent abatement
A65: Free rent value ($) | B65: =-F54 -> 2352 | C65: Base rent forgone in abatement period
A66: Free rent as % of scheduled base rent | B66: =IF(E54=0,0,-F54/E54) -> 0.026827848
A67: Tenant improvement allowance ($) | B67: =B14 -> 0 | C67: Landlord cost; none per client
...
